Workbook
Name ACTION: #REF!

Sheet Guidleline
A1: Guideline to make and understand Unit Test Case
A3: 1. Overview
A4: - In the template, Unit test cases are based on functions. Each sheet presents test cases for one function.
A5: - Cover: General information of the project and Unit Test cases
A6: - FunctionList: The list of Classes and Functions in the document. + To control that the number of Unit TC meets customer's requirement or the norm, user should fill value for 'Normal number of Test cases/KLOC'.
A7: + Click on Function link to open the related Test cases of the function. Note: You should create new Function sheet before creating the link
A8: - Test Report: provive the overview results of Functions Unit test: Test coverage, Test successful coverage (Summary, for normal/abnormal/boundary cases)
A9: Note: Should check the formula of "Sub Total" if you add more functions
A11: 2. Content in Test function sheet
A12: 2.1 Combination of test cases.
A13: - To verify that number of Unit TC meets customer's requirement or not. User has to fill number LOC of tested function and fill value of 'Normal number test cases/KLOC' item in FunctionList sheet, which is required by customer or normal value. The number of lacked TC is shown in 'Lack of test cases' item.
A14: - If the number of Unit TC does not meet the requirement, creator should explain the reasons.
... A47: - Test requirement: Brief description about requirements which are tested in this function, it is not mandatory.

Sheet Cover
B2: UNIT TEST CASE
A4: Project Name | B4: <Project Name> | E4: Creator
A5: Project Code | B5: <Project Code> | E5: Reviewer/Approver
A6: Document Code | B6: =B5&"_"&"XXX"&"_"&"vx.x" -> <Project Code>_XXX_vx.x | E6: Issue Date | F6: <Date when this test report is created>
E7: Version
A10: Record of change
A11: Effective Date | B11: Version | C11: Change Item | D11: *A,D,M | E11: Change description | F11: Reference
A12: <Date when these changes are effective> | F12: <List of documents which are refered in this version.>

Sheet FunctionList
E2: UNIT TEST CASE LIST
A4: Project Name | E4: =Cover!B4 -> <Project Name>
A5: Project Code | E5: =Cover!B5 -> <Project Code>
A6: Normal number of Test cases/KLOC | E6: 100
A7: Test Environment Setup Description | E7: <List enviroment requires in this system 1. Server 2. Database 3. Web Browser ... >
A10: No | B10: Requirement Name | C10: Class Name | D10: Function Name | E10: Function Code(Optional) | F10: Sheet Name | G10: Description | H10: Pre-Condition
A11: 1 | C11: Class1 | D11: Function A | E11: Function1 | F11: Function1
A12: 2 | C12: Class2 | D12: Function B | E12: Function2 | F12: Function2
A13: 3 | C13: Class3 | D13: Function C | E13: Function3 | F13: Function3

Sheet Test Report
A2: UNIT TEST REPORT
A4: Project Name | B4: =Cover!B4 -> <Project Name> | D4: Creator
A5: Project Code | B5: =Cover!B5 -> <Project Code> | D5: Reviewer/Approver
A6: Document Code | B6: =B5&"_"&"Test Report"&"_"&"vx.x" -> <Project Code>_Test Report_vx.x | D6: Issue Date | F6: <Date when this test report is created>
A7: Notes | B7: <List modules included in this release> ex: Release 1 includes 2 modules: Module1 and Module2
A11: No | B11: Function code | C11: Passed | D11: Failed | E11: Untested | F11: N | G11: A | H11: B | I11: Total Test Cases
A12: 1 | B12: Function1 | C12: =CheckDate!A7 -> 0 | D12: =CheckDate!C7 -> 0 | E12: =CheckDate!F7 -> 16 | F12: =CheckDate!L7 -> 4 | G12: =CheckDate!M7 -> 4 | H12: =CheckDate!N7 -> 8 | I12: =CheckDate!O7 -> 16
A13: 2 | B13: Function2 | C13: =DayInMonth!A7 -> 9 | D13: =DayInMonth!C7 -> 4 | E13: =DayInMonth!F7 -> 2 | F13: =DayInMonth!L7 -> 8 | G13: =DayInMonth!M7 -> 1 | H13: =DayInMonth!N7 -> 6 | I13: =DayInMonth!O7 -> 15
A14: 3 | B14: Function3 | C14: =Function3!A7 -> 12 | D14: =Function3!C7 -> 2 | E14: =Function3!F7 -> 1 | F14: =Function3!L7 -> 12 | G14: =Function3!M7 -> 2 | H14: =Function3!N7 -> 1 | I14: =Function3!O7 -> 15
B17: Sub total | C17: =SUM(C10:C16) -> 21 | D17: =SUM(D10:D16) -> 6 | E17: =SUM(E10:E16) -> 19 | F17: =SUM(F10:F16) -> 24 | G17: =SUM(G10:G16) -> 7 | H17: =SUM(H10:H16) -> 15 | I17: =SUM(I10:I16) -> 46
B19: Test coverage | D19: =(C17+D17)*100/(I17) -> 58.695652 | E19: %
B20: Test successful coverage | D20: =C17*100/(I17) -> 45.652174 | E20: %
B21: Normal case | D21: =F17*100/I17 -> 52.173913 | E21: %
B22: Abnormal case | D22: =G17*100/I17 -> 15.217391 | E22: %
B23: Boundary case | D23: =H17*100/I17 -> 32.608696 | E23: %

Sheet CheckDate
A2: Function Code | C2: =FunctionList!E11 -> Function1 | F2: Function Name | L2: =FunctionList!D11 -> Function A
A3: Created By | C3: <Developer Name> | F3: Executed By
A4: Lines of code | C4: 100 | F4: Lack of test cases | L4: =IF(FunctionList!E6<>"N/A",SUM(C4*FunctionList!E6/1000,- O7),"N/A") -> -6
A5: Test requirement | C5: <Brief description about requirements which are tested in this function>
A6: Passed | C6: Failed | F6: Untested | L6: N/A/B | O6: Total Test Cases
A7: =COUNTIF(F53:HQ53,"P") -> 0 | C7: =COUNTIF(F53:HQ53,"F") -> 0 | F7: =SUM(O7,- A7,- C7) -> 16 | L7: =COUNTIF(E52:HQ52,"N") -> 4 | M7: =COUNTIF(E52:HQ52,"A") -> 4 | N7: =COUNTIF(E52:HQ52,"B") -> 8 | O7: =COUNTA(E9:HT9) -> 16
F9: UTCID01 | G9: UTCID02 | H9: UTCID03 | I9: UTCID04 | J9: UTCID05 | K9: UTCID06 | L9: UTCID07 | M9: UTCID08 | N9: UTCID09 | O9: UTCID10 | P9: UTCID11 | Q9: UTCID12 | R9: UTCID13 | S9: UTCID14 | T9: UTCID15 | U9: UTCID16
A10: Condition | B10: Precondition
D11: Can connect with server
B14: Day
D15: 0 | F15: O
D16: 1 | H16: O | I16: O | J16: O | K16: O | L16: O
D17: 28 | P17: O
D18: 29 | Q18: O | R18: O | T18: O | U18: O
D19: 30 | N19: O | S19: O
D20: 31 | M20: O | O20: O
D21: 32 | G21: O
B23: Month
D24: 0 | H24: O
D25: 1 | F25: O | G25: O | J25: O | K25: O | L25: O
D26: 2 | P26: O | Q26: O | R26: O | S26: O | T26: O | U26: O
D27: 4 | N27: O | O27: O
D28: 12 | M28: O
D29: 13 | I29: O
B33: Year
D34: 999 | J34: O
D35: 1000 | L35: O
D36: 2000 | U36: O
D37: 2020 | R37: O | S37: O
D38: 2021 | E38: 3001 | F38: O | G38: O | H38: O | I38: O | N38: O | O38: O | P38: O | Q38: O
D39: 2100 | T39: O
D40: 3000 | M40: O
D41: 3001 | K41: O
A44: Confirm | B44: Return
D45: T | L45: O | M45: O | N45: O | P45: O | R45: O | U45: O
D46: F | F46: O | G46: O | H46: O | I46: O | J46: O | K46: O | O46: O | Q46: O | S46: O | T46: O
B47: Exception
B49: Log message
D50: "success" | L50: O | M50: O | N50: O | P50: O | R50: O | S50: O | U50: O
D51: "input1 is null" | F51: O | G51: O | H51: O | I51: O | J51: O | K51: O | O51: O | Q51: O | T51: O
...

Sheet DayInMonth
A2: Function Code | C2: =FunctionList!E12 -> Function2 | F2: Function Name | L2: =FunctionList!D12 -> Function B
A3: Created By | C3: <Developer Name> | F3: Executed By
A4: Lines of code | C4: 300 | F4: Lack of test cases | L4: =IF(FunctionList!E6<>"N/A",SUM(C4*FunctionList!E6/1000,- O7),"N/A") -> 15
A5: Test requirement | C5: <Brief description about requirements which are tested in this function>
A6: Passed | C6: Failed | F6: Untested | L6: N/A/B | O6: Total Test Cases
A7: =COUNTIF(F47:HQ47,"P") -> 9 | C7: =COUNTIF(F47:HQ47,"F") -> 4 | F7: =SUM(O7,- A7,- C7) -> 2 | L7: =COUNTIF(E46:HQ46,"N") -> 8 | M7: =COUNTIF(E46:HQ46,"A") -> 1 | N7: =COUNTIF(E46:HQ46,"B") -> 6 | O7: =COUNTA(E9:HT9) -> 15
F9: UTCID01 | G9: UTCID02 | H9: UTCID03 | I9: UTCID04 | J9: UTCID05 | K9: UTCID06 | L9: UTCID07 | M9: UTCID08 | N9: UTCID09 | O9: UTCID10 | P9: UTCID11 | Q9: UTCID12 | R9: UTCID13 | S9: UTCID14 | T9: UTCID15
A10: Condition | B10: Precondition
D11: Can connect with server
B14: Month
D15: 0 | F15: O
D16: 1 | H16: O | J16: O
D17: 2 | M17: O | N17: O | O17: O | P17: O
D18: 4 | L18: O
D19: 12 | K19: O
D20: 13 | G20: O | I20: O
B21: Year
D22: 999 | H22: O
D23: 1000 | J23: O
D24: 2000 | P24: O
D25: 2020 | F25: O | G25: O | N25: O
D26: 2021 | L26: O | M26: O
D27: 2100 | O27: O
D28: 3000 | K28: O
D29: 3001 | I29: O
A34: Confirm | B34: Return
D35: 0 | F35: O | G35: O | H35: O | I35: O
D36: 28 | M36: O | O36: O
D37: 29 | N37: O | P37: O
D38: 30 | L38: O
D39: 31 | J39: O | K39: O
B41: Exception
B43: Log message
D44: "success" | J44: O | K44: O | L44: O | M44: O | N44: O | O44: O | P44: O
D45: "input1 is null" | F45: O | G45: O | H45: O | I45: O
A46: Result | B46: Type(N : Normal, A : Abnormal, B : Boundary) | F46: B | G46: B | H46: B | I46: B | J46: B | K46: B | L46: N | M46: N | N46: N | O46: N | P46: N | Q46: N | R46: A | S46: N | T46: N
B47: Passed/Failed | F47: F | I47: P | J47: P | K47: F | L47: F | M47: P | N47: P | O47: P | P47: P | Q47: P | R47: F | S47: P | T47: P
B48: Executed Date | I48: 39141 | J48: 39142 | K48: 39143 | L48: 39144 | M48: 39145 | N48: 39146 | O48: 39147 | P48: 39148 | Q48: 39149 | R48: 39150 | S48: 39151 | T48: 39152
B49: Defect ID | F49: DFID001 | K49: DFID002 | L49: DFID004 | M49: DFID005 | N49: DFID006 | O49: DFID007 | P49: DFID008 | Q49: DFID009 | R49: DFID010 | S49: DFID011 | T49: DFID012

Sheet Function3
A2: Function Code | C2: =FunctionList!E13 -> Function3 | F2: Function Name | L2: =FunctionList!D13 -> Function C
A3: Created By | C3: <Developer Name> | F3: Executed By
A4: Lines of code | C4: 300 | F4: Lack of test cases | L4: =IF(FunctionList!E6<>"N/A",SUM(C4*FunctionList!E6/1000,- O7),"N/A") -> 15
A5: Test requirement | C5: <Brief description about requirements which are tested in this function>
A6: Passed | C6: Failed | F6: Untested | L6: N/A/B | O6: Total Test Cases
A7: =COUNTIF(F40:HQ40,"P") -> 12 | C7: =COUNTIF(F40:HQ40,"F") -> 2 | F7: =SUM(O7,- A7,- C7) -> 1 | L7: =COUNTIF(E39:HQ39,"N") -> 12 | M7: =COUNTIF(E39:HQ39,"A") -> 2 | N7: =COUNTIF(E39:HQ39,"B") -> 1 | O7: =COUNTA(E9:HT9) -> 15
F9: UTCID01 | G9: UTCID02 | H9: UTCID03 | I9: UTCID04 | J9: UTCID05 | K9: UTCID06 | L9: UTCID07 | M9: UTCID08 | N9: UTCID09 | O9: UTCID10 | P9: UTCID11 | Q9: UTCID12 | R9: UTCID13 | S9: UTCID14 | T9: UTCID15
A10: Condition | B10: Precondition
D11: Can connect with server
B14: Input1
D15: "1"
D16: ""
D17: null
B18: Input2
D19: >=5 & <= 10
D20: 5
D21: 10
A31: Confirm | B31: Return
D32: 1
D33: 2
B34: Exception
B36: Log message
D37: "success"
D38: "input1 is null"
A39: Result | B39: Type(N : Normal, A : Abnormal, B : Boundary) | F39: N | G39: N | H39: N | I39: N | J39: N | K39: B | L39: A | M39: N | N39: N | O39: N | P39: N | Q39: N | R39: A | S39: N | T39: N
B40: Passed/Failed | F40: P | G40: P | H40: P | I40: P | J40: P | K40: F | L40: F | M40: P | N40: P | O40: P | P40: P | Q40: P | S40: P | T40: P
B41: Executed Date | F41: 39139 | G41: 39139 | H41: 39140 | I41: 39141 | J41: 39142 | K41: 39143 | L41: 39144 | M41: 39145 | N41: 39146 | O41: 39147 | P41: 39148 | Q41: 39149 | R41: 39150 | S41: 39151 | T41: 39152
B42: Defect ID | K42: DFID002 | L42: DFID004 | M42: DFID005 | N42: DFID006 | O42: DFID007 | P42: DFID008 | Q42: DFID009 | R42: DFID010 | S42: DFID011 | T42: DFID012

Sheet Example
A2: Function Code | C2: =FunctionList!E11 -> Function1 | F2: Function Name | L2: =FunctionList!D11 -> Function A
A3: Created By | C3: <Developer Name> | F3: Executed By
A4: Lines of code | C4: 100 | F4: Lack of test cases | L4: =IF(FunctionList!E6<>"N/A",SUM(C4*FunctionList!E6/1000,- O7),"N/A") -> -5
A5: Test requirement | C5: <Brief description about requirements which are tested in this function>
A6: Passed | C6: Failed | F6: Untested | L6: N/A/B | O6: Total Test Cases
A7: =COUNTIF(F47:HQ47,"P") -> 0 | C7: =COUNTIF(F47:HQ47,"F") -> 0 | F7: =SUM(O7,- A7,- C7) -> 15 | L7: =COUNTIF(E46:HQ46,"N") -> 0 | M7: =COUNTIF(E46:HQ46,"A") -> 0 | N7: =COUNTIF(E46:HQ46,"B") -> 0 | O7: =COUNTA(E9:HT9) -> 15
F9: UTCID01 | G9: UTCID02 | H9: UTCID02 | I9: UTCID02 | J9: UTCID02 | K9: UTCID02 | L9: UTCID07 | M9: UTCID08 | N9: UTCID09 | O9: UTCID10 | P9: UTCID11 | Q9: UTCID12 | R9: UTCID13 | S9: UTCID14 | T9: UTCID15
A10: Condition | B10: Precondition
B14: a
D15: -2 | F15: O
D16: -1 | L16: O
D17: 0 | G17: O | H17: O | I17: O
D18: 1 | J18: O | K18: O
B19: b
D20: 0 | G20: O | H20: O
D21: -2 | J21: O | K21: O | L21: O
D22: 2 | I22: O
B23: c
D24: 0 | G24: O
D25: 1 | H25: O | I25: O | J25: O
D26: 3 | L26: O
D27: 5 | K27: O
A33: Confirm | B33: Return
B34: list
D35: null | F35: O | H35: O | K35: O
D36: size = 0 | G36: O
D37: {-1/2} | I37: O
D38: {1,1} | J38: O
D39: {1,-3} | L39: O
B40: Exception
B42: Log message
D43: "please input a>= -1" | F43: O
A45: Result | B45: Type(N : Normal, A : Abnormal, B : Boundary) | F45: A | G45: N | H45: N | I45: N | J45: N | K45: N | L45: B
B46: Passed/Failed
B47: Executed Date | F47: 39139 | G47: 39139 | H47: 39139 | I47: 39139 | J47: 39139 | K47: 39139 | L47: 39144
B48: Defect ID
